Workbook

Sheet 明細
A1: 利用日 | B1: 利用店名 | C1: カテゴリ | D1: 金額 | E1: お支払月 | F1: 備考
A2: 2025-11-27 | B2: 関⻄電⼒ 電気 | C2: 水道光熱費 | D2: 6309 | E2: 1月 | F2: ２５年１１⽉ ◎
A3: 2025-12-02 | B3: ＡＭＡＺＯＮ．ＣＯ．ＪＰ | C3: ネットショッピング | D3: 11480 | E3: 1月 | F3: ◎
A4: 2025-12-02 | B4: ダイエー | C4: スーパー・食料品 | D4: 725 | E4: 1月 | F4: ◎
A5: 2025-12-06 | B5: ニトリ | C5: 日用品・インテリア | D5: 3012 | E5: 1月 | F5: ◎
A6: 2025-12-07 | B6: ＡＭＡＺＯＮ．ＣＯ．ＪＰ | C6: ネットショッピング | D6: 31980 | E6: 1月 | F6: ◎
A7: 2025-12-07 | B7: ＡＭＡＺＯＮ．ＣＯ．ＪＰ | C7: ネットショッピング | D7: 21949 | E7: 1月 | F7: ◎
A8: 2025-12-10 | B8: 関⻄電⼒ガス | C8: 水道光熱費 | D8: 4910 | E8: 1月 | F8: ２５年１２⽉ ◎
A9: 2025-12-26 | B9: Ｒｅｎｔｉｏ | C9: 通信費・サブスク | D9: 6282 | E9: 1月 | F9: ◎
A10: 2025-12-28 | B10: Ａｍａｚｏｎプライム会費 | C10: 通信費・サブスク | D10: 600 | E10: 1月 | F10: ◎
A11: 2025-12-29 | B11: ＡＭＡＺＯＮ．ＣＯ．ＪＰ | C11: ネットショッピング | D11: 34176 | E11: 1月 | F11: ◎
A12: 2025-12-30 | B12: キャトルエピス 静岡店 | C12: 外食・カフェ | D12: 2928 | E12: 1月 | F12: ◎
A13: 2025-12-30 | B13: ななや 藤枝本店 | C13: 外食・カフェ | D13: 8359 | E13: 1月 | F13: ◎
... A197: 2026-04-24 | B197: 関⻄電⼒ 電気 | C197: 水道光熱費 | D197: 6003 | E197: 6月 | F197: ２６年 ４⽉ ◎
A198: 2026-04-27 | B198: 遅延損害⾦（ショッピング利⽤） | C198: 手数料・利息 | D198: 2741 | E198: 6月
A199: 2026-05-14 | B199: 関⻄電⼒ガス | C199: 水道光熱費 | D199: 6160 | E199: 6月 | F199: ２６年 ５⽉ ◎
A200: 2026-05-15 | B200: 回収事務⼿数料 | C200: 手数料・利息 | D200: 495 | E200: 6月 | F200: ４⽉分
A201: 2026-05-22 | B201: ドン‧キホーテ⻄宮店 | C201: 日用品・インテリア | D201: 4369 | E201: 6月 | F201: ◎
A202: 2026-05-22 | B202: ヤマダデンキ ＷＥＢ．ＣＯＭ | C202: ネットショッピング | D202: 15120 | E202: 6月 | F202: ◎
A203: 2026-05-23 | B203: マクドナルド | C203: 外食・カフェ | D203: 1080 | E203: 6月 | F203: ◎
A204: 2026-05-23 | B204: オーケー 新在家店 | C204: スーパー・食料品 | D204: 3497 | E204: 6月 | F204: ◎
A205: 2026-05-25 | B205: ＡＭＡＺＯＮ．ＣＯ．ＪＰ | C205: ネットショッピング | D205: 3843 | E205: 6月 | F205: ◎
A206: 2026-05-25 | B206: ソニ－⽣命保険料 | C206: 保険 | D206: 55420 | E206: 6月 | F206: ◎
A207: 2026-05-28 | B207: Ａｍａｚｏｎプライム会費 | C207: 通信費・サブスク | D207: 600 | E207: 6月 | F207: ◎
A208: 2026-05-28 | B208: ファミリーマート | C208: コンビニ | D208: 700 | E208: 6月 | F208: ファミリーマート 旧居留地東 ◎
A209: 2026-05-28 | B209: ａｇｏｄａ | C209: 旅行・宿泊（予約サイト） | D209: 8884 | E209: 6月 | F209: ◎
A210: 2026-05-28 | B210: ａｇｏｄａ | C210: 旅行・宿泊（予約サイト） | D210: 9734 | E210: 6月 | F210: ◎
... A286: 2026-06-29 | B286: 海外キャッシュサービス利息 | C286: 手数料・利息 | D286: 146 | E286: 7月 | F286: (海外キャッシュサービス ご返済期間28日間)
A287: 2026-06-29 | B287: ＡＴＭ利⽤⼿数料 海外キャッシング | C287: 手数料・利息 | D287: 220 | E287: 7月
A288: 2026-06-30 | B288: フェリカポケットマーケティング（株） | C288: 通信費・サブスク | D288: 20000 | E288: 7月 | F288: ◎
A289: 2026-06-30 | B289: フェリカポケットマーケティング（株） | C289: 通信費・サブスク | D289: 20000 | E289: 7月 | F289: ◎
A290: 2026-06-30 | B290: POMPI IL REGNO (ROMA ) | C290: 外食・カフェ | D290: 1150 | E290: 7月 | F290: 6.00 EUR 191.822 07 01 ◎
A291: 2026-06-30 | B291: FREENOW* DSO7TU-2 (FREE-NOW.COM/) | C291: 交通費 | D291: 2205 | E291: 7月 | F291: 11.50 EUR 191.822 07 01 ◎
A292: 2026-06-30 | B292: TRECAFFE RISTORANTE CA (ROMA ) | C292: 外食・カフェ | D292: 383 | E292: 7月 | F292: 2.00 EUR 191.822 07 01 ◎
A293: 2026-06-30 | B293: CARREFOUR EXPRESS (ROMA ) | C293: スーパー・食料品 | D293: 1290 | E293: 7月 | F293: 6.73 EUR 191.822 07 01 ◎
A294: 2026-06-30 | B294: FLOR (ROMA ) | C294: 外食・カフェ | D294: 767 | E294: 7月 | F294: 4.00 EUR 191.822 07 01 ◎
A295: 2026-06-30 | B295: LARINASCENTE TRITONE 4 (ROMA ) | C295: 外食・カフェ | D295: 7001 | E295: 7月 | F295: 36.50 EUR 191.822 07 01 ◎
A296: 2026-06-30 | B296: RISTORANTE TEMA (ROMA ) | C296: 外食・カフェ | D296: 9591 | E296: 7月 | F296: 50.00 EUR 191.822 07 01 ◎
A297: 2026-06-30 | B297: CAFFE' VALORANI (ROMA ) | C297: 外食・カフェ | D297: 479 | E297: 7月 | F297: 2.50 EUR 191.822 07 01 ◎
A298: 2026-06-30 | B298: LA CASA DEL CAFFE' TAZZA (ROMA ) | C298: 外食・カフェ | D298: 4891 | E298: 7月 | F298: 25.50 EUR 191.822 07 01 ◎
...

Sheet 月別サマリー
A1: 三井住友カード ご利用明細 月別×カテゴリ集計（お支払月ベース）
A3: カテゴリ | B3: 1月(支払) | C3: 2月(支払) | D3: 3月(支払) | E3: 4月(支払) | F3: 5月(支払) | G3: 6月(支払) | H3: 7月(支払) | I3: 合計
A4: 水道光熱費 | B4: =SUMIFS(明細!$D$2:$D$301,明細!$C$2:$C$301,$A4,明細!$E$2:$E$301,B$3) | C4: =SUMIFS(明細!$D$2:$D$301,明細!$C$2:$C$301,$A4,明細!$E$2:$E$301,C$3) | D4: =SUMIFS(明細!$D$2:$D$301,明細!$C$2:$C$301,$A4,明細!$E$2:$E$301,D$3) | E4: =SUMIFS(明細!$D$2:$D$301,明細!$C$2:$C$301,$A4,明細!$E$2:$E$301,E$3) | F4: =SUMIFS(明細!$D$2:$D$301,明細!$C$2:$C$301,$A4,明細!$E$2:$E$301,F$3) | G4: =SUMIFS(明細!$D$2:$D$301,明細!$C$2:$C$301,$A4,明細!$E$2:$E$301,G$3) | H4: =SUMIFS(明細!$D$2:$D$301,明細!$C$2:$C$301,$A4,明細!$E$2:$E$301,H$3) | I4: =SUM(B4:H4)
A5: 保険 | B5: =SUMIFS(明細!$D$2:$D$301,明細!$C$2:$C$301,$A5,明細!$E$2:$E$301,B$3) | C5: =SUMIFS(明細!$D$2:$D$301,明細!$C$2:$C$301,$A5,明細!$E$2:$E$301,C$3) | D5: =SUMIFS(明細!$D$2:$D$301,明細!$C$2:$C$301,$A5,明細!$E$2:$E$301,D$3) | E5: =SUMIFS(明細!$D$2:$D$301,明細!$C$2:$C$301,$A5,明細!$E$2:$E$301,E$3) | F5: =SUMIFS(明細!$D$2:$D$301,明細!$C$2:$C$301,$A5,明細!$E$2:$E$301,F$3) | G5: =SUMIFS(明細!$D$2:$D$301,明細!$C$2:$C$301,$A5,明細!$E$2:$E$301,G$3) | H5: =SUMIFS(明細!$D$2:$D$301,明細!$C$2:$C$301,$A5,明細!$E$2:$E$301,H$3) | I5: =SUM(B5:H5)
A6: 通信費・サブスク | B6: =SUMIFS(明細!$D$2:$D$301,明細!$C$2:$C$301,$A6,明細!$E$2:$E$301,B$3) | C6: =SUMIFS(明細!$D$2:$D$301,明細!$C$2:$C$301,$A6,明細!$E$2:$E$301,C$3) | D6: =SUMIFS(明細!$D$2:$D$301,明細!$C$2:$C$301,$A6,明細!$E$2:$E$301,D$3) | E6: =SUMIFS(明細!$D$2:$D$301,明細!$C$2:$C$301,$A6,明細!$E$2:$E$301,E$3) | F6: =SUMIFS(明細!$D$2:$D$301,明細!$C$2:$C$301,$A6,明細!$E$2:$E$301,F$3) | G6: =SUMIFS(明細!$D$2:$D$301,明細!$C$2:$C$301,$A6,明細!$E$2:$E$301,G$3) | H6: =SUMIFS(明細!$D$2:$D$301,明細!$C$2:$C$301,$A6,明細!$E$2:$E$301,H$3) | I6: =SUM(B6:H6)
A7: コンビニ | B7: =SUMIFS(明細!$D$2:$D$301,明細!$C$2:$C$301,$A7,明細!$E$2:$E$301,B$3) | C7: =SUMIFS(明細!$D$2:$D$301,明細!$C$2:$C$301,$A7,明細!$E$2:$E$301,C$3) | D7: =SUMIFS(明細!$D$2:$D$301,明細!$C$2:$C$301,$A7,明細!$E$2:$E$301,D$3) | E7: =SUMIFS(明細!$D$2:$D$301,明細!$C$2:$C$301,$A7,明細!$E$2:$E$301,E$3) | F7: =SUMIFS(明細!$D$2:$D$301,明細!$C$2:$C$301,$A7,明細!$E$2:$E$301,F$3) | G7: =SUMIFS(明細!$D$2:$D$301,明細!$C$2:$C$301,$A7,明細!$E$2:$E$301,G$3) | H7: =SUMIFS(明細!$D$2:$D$301,明細!$C$2:$C$301,$A7,明細!$E$2:$E$301,H$3) | I7: =SUM(B7:H7)
A8: スーパー・食料品 | B8: =SUMIFS(明細!$D$2:$D$301,明細!$C$2:$C$301,$A8,明細!$E$2:$E$301,B$3) | C8: =SUMIFS(明細!$D$2:$D$301,明細!$C$2:$C$301,$A8,明細!$E$2:$E$301,C$3) | D8: =SUMIFS(明細!$D$2:$D$301,明細!$C$2:$C$301,$A8,明細!$E$2:$E$301,D$3) | E8: =SUMIFS(明細!$D$2:$D$301,明細!$C$2:$C$301,$A8,明細!$E$2:$E$301,E$3) | F8: =SUMIFS(明細!$D$2:$D$301,明細!$C$2:$C$301,$A8,明細!$E$2:$E$301,F$3) | G8: =SUMIFS(明細!$D$2:$D$301,明細!$C$2:$C$301,$A8,明細!$E$2:$E$301,G$3) | H8: =SUMIFS(明細!$D$2:$D$301,明細!$C$2:$C$301,$A8,明細!$E$2:$E$301,H$3) | I8: =SUM(B8:H8)
A9: ドラッグストア | B9: =SUMIFS(明細!$D$2:$D$301,明細!$C$2:$C$301,$A9,明細!$E$2:$E$301,B$3) | C9: =SUMIFS(明細!$D$2:$D$301,明細!$C$2:$C$301,$A9,明細!$E$2:$E$301,C$3) | D9: =SUMIFS(明細!$D$2:$D$301,明細!$C$2:$C$301,$A9,明細!$E$2:$E$301,D$3) | E9: =SUMIFS(明細!$D$2:$D$301,明細!$C$2:$C$301,$A9,明細!$E$2:$E$301,E$3) | F9: =SUMIFS(明細!$D$2:$D$301,明細!$C$2:$C$301,$A9,明細!$E$2:$E$301,F$3) | G9: =SUMIFS(明細!$D$2:$D$301,明細!$C$2:$C$301,$A9,明細!$E$2:$E$301,G$3) | H9: =SUMIFS(明細!$D$2:$D$301,明細!$C$2:$C$301,$A9,明細!$E$2:$E$301,H$3) | I9: =SUM(B9:H9)
A10: 外食・カフェ | B10: =SUMIFS(明細!$D$2:$D$301,明細!$C$2:$C$301,$A10,明細!$E$2:$E$301,B$3) | C10: =SUMIFS(明細!$D$2:$D$301,明細!$C$2:$C$301,$A10,明細!$E$2:$E$301,C$3) | D10: =SUMIFS(明細!$D$2:$D$301,明細!$C$2:$C$301,$A10,明細!$E$2:$E$301,D$3) | E10: =SUMIFS(明細!$D$2:$D$301,明細!$C$2:$C$301,$A10,明細!$E$2:$E$301,E$3) | F10: =SUMIFS(明細!$D$2:$D$301,明細!$C$2:$C$301,$A10,明細!$E$2:$E$301,F$3) | G10: =SUMIFS(明細!$D$2:$D$301,明細!$C$2:$C$301,$A10,明細!$E$2:$E$301,G$3) | H10: =SUMIFS(明細!$D$2:$D$301,明細!$C$2:$C$301,$A10,明細!$E$2:$E$301,H$3) | I10: =SUM(B10:H10)
A11: ショッピングモール・百貨店 | B11: =SUMIFS(明細!$D$2:$D$301,明細!$C$2:$C$301,$A11,明細!$E$2:$E$301,B$3) | C11: =SUMIFS(明細!$D$2:$D$301,明細!$C$2:$C$301,$A11,明細!$E$2:$E$301,C$3) | D11: =SUMIFS(明細!$D$2:$D$301,明細!$C$2:$C$301,$A11,明細!$E$2:$E$301,D$3) | E11: =SUMIFS(明細!$D$2:$D$301,明細!$C$2:$C$301,$A11,明細!$E$2:$E$301,E$3) | F11: =SUMIFS(明細!$D$2:$D$301,明細!$C$2:$C$301,$A11,明細!$E$2:$E$301,F$3) | G11: =SUMIFS(明細!$D$2:$D$301,明細!$C$2:$C$301,$A11,明細!$E$2:$E$301,G$3) | H11: =SUMIFS(明細!$D$2:$D$301,明細!$C$2:$C$301,$A11,明細!$E$2:$E$301,H$3) | I11: =SUM(B11:H11)
A12: 日用品・インテリア | B12: =SUMIFS(明細!$D$2:$D$301,明細!$C$2:$C$301,$A12,明細!$E$2:$E$301,B$3) | C12: =SUMIFS(明細!$D$2:$D$301,明細!$C$2:$C$301,$A12,明細!$E$2:$E$301,C$3) | D12: =SUMIFS(明細!$D$2:$D$301,明細!$C$2:$C$301,$A12,明細!$E$2:$E$301,D$3) | E12: =SUMIFS(明細!$D$2:$D$301,明細!$C$2:$C$301,$A12,明細!$E$2:$E$301,E$3) | F12: =SUMIFS(明細!$D$2:$D$301,明細!$C$2:$C$301,$A12,明細!$E$2:$E$301,F$3) | G12: =SUMIFS(明細!$D$2:$D$301,明細!$C$2:$C$301,$A12,明細!$E$2:$E$301,G$3) | H12: =SUMIFS(明細!$D$2:$D$301,明細!$C$2:$C$301,$A12,明細!$E$2:$E$301,H$3) | I12: =SUM(B12:H12)
A13: ファッション・美容 | B13: =SUMIFS(明細!$D$2:$D$301,明細!$C$2:$C$301,$A13,明細!$E$2:$E$301,B$3) | C13: =SUMIFS(明細!$D$2:$D$301,明細!$C$2:$C$301,$A13,明細!$E$2:$E$301,C$3) | D13: =SUMIFS(明細!$D$2:$D$301,明細!$C$2:$C$301,$A13,明細!$E$2:$E$301,D$3) | E13: =SUMIFS(明細!$D$2:$D$301,明細!$C$2:$C$301,$A13,明細!$E$2:$E$301,E$3) | F13: =SUMIFS(明細!$D$2:$D$301,明細!$C$2:$C$301,$A13,明細!$E$2:$E$301,F$3) | G13: =SUMIFS(明細!$D$2:$D$301,明細!$C$2:$C$301,$A13,明細!$E$2:$E$301,G$3) | H13: =SUMIFS(明細!$D$2:$D$301,明細!$C$2:$C$301,$A13,明細!$E$2:$E$301,H$3) | I13: =SUM(B13:H13)
A14: ネットショッピング | B14: =SUMIFS(明細!$D$2:$D$301,明細!$C$2:$C$301,$A14,明細!$E$2:$E$301,B$3) | C14: =SUMIFS(明細!$D$2:$D$301,明細!$C$2:$C$301,$A14,明細!$E$2:$E$301,C$3) | D14: =SUMIFS(明細!$D$2:$D$301,明細!$C$2:$C$301,$A14,明細!$E$2:$E$301,D$3) | E14: =SUMIFS(明細!$D$2:$D$301,明細!$C$2:$C$301,$A14,明細!$E$2:$E$301,E$3) | F14: =SUMIFS(明細!$D$2:$D$301,明細!$C$2:$C$301,$A14,明細!$E$2:$E$301,F$3) | G14: =SUMIFS(明細!$D$2:$D$301,明細!$C$2:$C$301,$A14,明細!$E$2:$E$301,G$3) | H14: =SUMIFS(明細!$D$2:$D$301,明細!$C$2:$C$301,$A14,明細!$E$2:$E$301,H$3) | I14: =SUM(B14:H14)
A15: 交通費 | B15: =SUMIFS(明細!$D$2:$D$301,明細!$C$2:$C$301,$A15,明細!$E$2:$E$301,B$3) | C15: =SUMIFS(明細!$D$2:$D$301,明細!$C$2:$C$301,$A15,明細!$E$2:$E$301,C$3) | D15: =SUMIFS(明細!$D$2:$D$301,明細!$C$2:$C$301,$A15,明細!$E$2:$E$301,D$3) | E15: =SUMIFS(明細!$D$2:$D$301,明細!$C$2:$C$301,$A15,明細!$E$2:$E$301,E$3) | F15: =SUMIFS(明細!$D$2:$D$301,明細!$C$2:$C$301,$A15,明細!$E$2:$E$301,F$3) | G15: =SUMIFS(明細!$D$2:$D$301,明細!$C$2:$C$301,$A15,明細!$E$2:$E$301,G$3) | H15: =SUMIFS(明細!$D$2:$D$301,明細!$C$2:$C$301,$A15,明細!$E$2:$E$301,H$3) | I15: =SUM(B15:H15)
... A20: その他 | B20: =SUMIFS(明細!$D$2:$D$301,明細!$C$2:$C$301,$A20,明細!$E$2:$E$301,B$3) | C20: =SUMIFS(明細!$D$2:$D$301,明細!$C$2:$C$301,$A20,明細!$E$2:$E$301,C$3) | D20: =SUMIFS(明細!$D$2:$D$301,明細!$C$2:$C$301,$A20,明細!$E$2:$E$301,D$3) | E20: =SUMIFS(明細!$D$2:$D$301,明細!$C$2:$C$301,$A20,明細!$E$2:$E$301,E$3) | F20: =SUMIFS(明細!$D$2:$D$301,明細!$C$2:$C$301,$A20,明細!$E$2:$E$301,F$3) | G20: =SUMIFS(明細!$D$2:$D$301,明細!$C$2:$C$301,$A20,明細!$E$2:$E$301,G$3) | H20: =SUMIFS(明細!$D$2:$D$301,明細!$C$2:$C$301,$A20,明細!$E$2:$E$301,H$3) | I20: =SUM(B20:H20)
A21: 合計 | B21: =SUM(B4:B20) | C21: =SUM(C4:C20) | D21: =SUM(D4:D20) | E21: =SUM(E4:E20) | F21: =SUM(F4:F20) | G21: =SUM(G4:G20) | H21: =SUM(H4:H20) | I21: =SUM(I4:I20)
A23: 参考：各明細書のお支払い合計額
A24: お支払月 | B24: お支払日 | C24: お支払い合計額(明細書記載)
A25: 1月(支払) | B25: 2026-01-26 | C25: 284227
A26: 2月(支払) | B26: 2026-02-26 | C26: 110839
A27: 3月(支払) | B27: 2026-03-26 | C27: 70479
A28: 4月(支払) | B28: 2026-04-27 | C28: 623156
A29: 5月(支払) | B29: 2026-05-26 | C29: 159905
A30: 6月(支払) | B30: 2026-06-26 | C30: 128813
A31: 7月(支払) | B31: 2026-07-27 | C31: 472489

Sheet カテゴリ別集計
A1: カテゴリ別集計（2026年1月〜7月支払 全体）
A3: カテゴリ | B3: 金額 | C3: 構成比
A4: 水道光熱費 | B4: =SUMIF(明細!$C$2:$C$301,$A4,明細!$D$2:$D$301) | C4: =B4/$B$21
A5: 保険 | B5: =SUMIF(明細!$C$2:$C$301,$A5,明細!$D$2:$D$301) | C5: =B5/$B$21
A6: 通信費・サブスク | B6: =SUMIF(明細!$C$2:$C$301,$A6,明細!$D$2:$D$301) | C6: =B6/$B$21
A7: コンビニ | B7: =SUMIF(明細!$C$2:$C$301,$A7,明細!$D$2:$D$301) | C7: =B7/$B$21
A8: スーパー・食料品 | B8: =SUMIF(明細!$C$2:$C$301,$A8,明細!$D$2:$D$301) | C8: =B8/$B$21
A9: ドラッグストア | B9: =SUMIF(明細!$C$2:$C$301,$A9,明細!$D$2:$D$301) | C9: =B9/$B$21
A10: 外食・カフェ | B10: =SUMIF(明細!$C$2:$C$301,$A10,明細!$D$2:$D$301) | C10: =B10/$B$21
A11: ショッピングモール・百貨店 | B11: =SUMIF(明細!$C$2:$C$301,$A11,明細!$D$2:$D$301) | C11: =B11/$B$21
A12: 日用品・インテリア | B12: =SUMIF(明細!$C$2:$C$301,$A12,明細!$D$2:$D$301) | C12: =B12/$B$21
A13: ファッション・美容 | B13: =SUMIF(明細!$C$2:$C$301,$A13,明細!$D$2:$D$301) | C13: =B13/$B$21
A14: ネットショッピング | B14: =SUMIF(明細!$C$2:$C$301,$A14,明細!$D$2:$D$301) | C14: =B14/$B$21
A15: 交通費 | B15: =SUMIF(明細!$C$2:$C$301,$A15,明細!$D$2:$D$301) | C15: =B15/$B$21
... A20: その他 | B20: =SUMIF(明細!$C$2:$C$301,$A20,明細!$D$2:$D$301) | C20: =B20/$B$21
A21: 合計 | B21: =SUM(B4:B20) | C21: =B21/B21
